INFO:__main__:Fitting model at time: 2021-09-09 09:16:48.219230
INFO:__main__:Made it past here!
Traceback (most recent call last):
  File "train_model.py", line 173, in <module>
    model, train_loss, test_loss = train_model(
  File "train_model.py", line 115, in train_model
    out = model(batch.to(DEVICE))
  File "/zhome/2b/7/117471/Thesis/venv-thesis/lib/python3.8/site-packages/torch/nn/modules/module.py", line 1051, in _call_impl
    return forward_call(*input, **kwargs)
  File "/zhome/2b/7/117471/Thesis/src/models/models.py", line 461, in forward
    x = self.conv2_sh(x=x, edge_index=edge_index)  # , edge_weight=edge_weight)
  File "/zhome/2b/7/117471/Thesis/venv-thesis/lib/python3.8/site-packages/torch/nn/modules/module.py", line 1051, in _call_impl
    return forward_call(*input, **kwargs)
  File "/zhome/2b/7/117471/Thesis/venv-thesis/lib/python3.8/site-packages/torch_geometric/nn/conv/gatv2_conv.py", line 154, in forward
    out = self.propagate(edge_index, x=(x_l, x_r), size=size)
  File "/zhome/2b/7/117471/Thesis/venv-thesis/lib/python3.8/site-packages/torch_geometric/nn/conv/message_passing.py", line 233, in propagate
    coll_dict = self.__collect__(self.__user_args__, edge_index, size,
  File "/zhome/2b/7/117471/Thesis/venv-thesis/lib/python3.8/site-packages/torch_geometric/nn/conv/message_passing.py", line 157, in __collect__
    data = self.__lift__(data, edge_index,
  File "/zhome/2b/7/117471/Thesis/venv-thesis/lib/python3.8/site-packages/torch_geometric/nn/conv/message_passing.py", line 127, in __lift__
    return src.index_select(self.node_dim, index)
RuntimeError: CUDA out of memory. Tried to allocate 222.00 MiB (GPU 0; 15.78 GiB total capacity; 13.83 GiB already allocated; 191.50 MiB free; 14.27 GiB reserved in total by PyTorch)
